Workbook
Name Slicer_Category: #N/A
Name Slicer_Discount_Band: #N/A
Name Slicer_Quarter: #N/A
Name Slicer_Region: #N/A
Name Slicer_State: #N/A
Name Slicer_Year: #N/A

Sheet Superstore sales dataset
A1: Row ID | B1: Order ID | C1: Order Date | D1: Ship Date | E1: Ship Mode | F1: Customer ID | G1: Customer Name | H1: Segment | I1: Country | J1: City | K1: State | L1: Postal Code | M1: Region | N1: Product ID | O1: Category | P1: Sub-Category | Q1: Product Name | R1: Sales | S1: Quantity | T1: Discount | U1: Profit | V1: Discount Band | W1: Year | X1: Quarter | Y1: Month
A2: 1 | B2: CA-2016-152156 | C2: 42682 | D2: 42685 | E2: Second Class | F2: CG-12520 | G2: Claire Gute | H2: Consumer | I2: United States | J2: Henderson | K2: Kentucky | L2: 42420 | M2: South | N2: FUR-BO-10001798 | O2: Furniture | P2: Bookcases | Q2: Bush Somerset Collection Bookcase | R2: 261.96 | S2: 2 | T2: 0 | U2: 41.9136 | V2: {=_xlfn.IFS(Suoerstore_sales[[#This Row],[Discount]]<=0.05,"0-5%",Suoerstore_sales[[#This Row],[Discount]]<=0.1,"5-10%",Suoerstore_sales[[#This Row],[Discount]]<=0.2,"10-20%",TRUE,"20%+")} -> 0-5% | W2: =YEAR(Suoerstore_sales[[#This Row],[Order Date]]) -> 2016 | X2: ="Q"&ROUNDUP(MONTH(Suoerstore_sales[[#This Row],[Order Date]])/3,0) -> Q4 | Y2: =MONTH(Suoerstore_sales[[#This Row],[Order Date]]) -> 11
A3: 2 | B3: CA-2016-152156 | C3: 42682 | D3: 42685 | E3: Second Class | F3: CG-12520 | G3: Claire Gute | H3: Consumer | I3: United States | J3: Henderson | K3: Kentucky | L3: 42420 | M3: South | N3: FUR-CH-10000454 | O3: Furniture | P3: Chairs | Q3: Hon Deluxe Fabric Upholstered Stacking Chairs, Rounded Back | R3: 731.94 | S3: 3 | T3: 0 | U3: 219.582 | V3: {=_xlfn.IFS(Suoerstore_sales[[#This Row],[Discount]]<=0.05,"0-5%",Suoerstore_sales[[#This Row],[Discount]]<=0.1,"5-10%",Suoerstore_sales[[#This Row],[Discount]]<=0.2,"10-20%",TRUE,"20%+")} -> 0-5% | W3: =YEAR(Suoerstore_sales[[#This Row],[Order Date]]) -> 2016 | X3: ="Q"&ROUNDUP(MONTH(Suoerstore_sales[[#This Row],[Order Date]])/3,0) -> Q4 | Y3: =MONTH(Suoerstore_sales[[#This Row],[Order Date]]) -> 11
A4: 3 | B4: CA-2016-138688 | C4: 42533 | D4: 42537 | E4: Second Class | F4: DV-13045 | G4: Darrin Van Huff | H4: Corporate | I4: United States | J4: Los Angeles | K4: California | L4: 90036 | M4: West | N4: OFF-LA-10000240 | O4: Office Supplies | P4: Labels | Q4: Self-Adhesive Address Labels for Typewriters by Universal | R4: 14.62 | S4: 2 | T4: 0 | U4: 6.8714 | V4: {=_xlfn.IFS(Suoerstore_sales[[#This Row],[Discount]]<=0.05,"0-5%",Suoerstore_sales[[#This Row],[Discount]]<=0.1,"5-10%",Suoerstore_sales[[#This Row],[Discount]]<=0.2,"10-20%",TRUE,"20%+")} -> 0-5% | W4: =YEAR(Suoerstore_sales[[#This Row],[Order Date]]) -> 2016 | X4: ="Q"&ROUNDUP(MONTH(Suoerstore_sales[[#This Row],[Order Date]])/3,0) -> Q2 | Y4: =MONTH(Suoerstore_sales[[#This Row],[Order Date]]) -> 6
A5: 4 | B5: US-2015-108966 | C5: 42288 | D5: 42295 | E5: Standard Class | F5: SO-20335 | G5: Sean O'Donnell | H5: Consumer | I5: United States | J5: Fort Lauderdale | K5: Florida | L5: 33311 | M5: South | N5: FUR-TA-10000577 | O5: Furniture | P5: Tables | Q5: Bretford CR4500 Series Slim Rectangular Table | R5: 957.5775 | S5: 5 | T5: 0.45 | U5: -383.031 | V5: {=_xlfn.IFS(Suoerstore_sales[[#This Row],[Discount]]<=0.05,"0-5%",Suoerstore_sales[[#This Row],[Discount]]<=0.1,"5-10%",Suoerstore_sales[[#This Row],[Discount]]<=0.2,"10-20%",TRUE,"20%+")} -> 20%+ | W5: =YEAR(Suoerstore_sales[[#This Row],[Order Date]]) -> 2015 | X5: ="Q"&ROUNDUP(MONTH(Suoerstore_sales[[#This Row],[Order Date]])/3,0) -> Q4 | Y5: =MONTH(Suoerstore_sales[[#This Row],[Order Date]]) -> 10
A6: 5 | B6: US-2015-108966 | C6: 42288 | D6: 42295 | E6: Standard Class | F6: SO-20335 | G6: Sean O'Donnell | H6: Consumer | I6: United States | J6: Fort Lauderdale | K6: Florida | L6: 33311 | M6: South | N6: OFF-ST-10000760 | O6: Office Supplies | P6: Storage | Q6: Eldon Fold 'N Roll Cart System | R6: 22.368 | S6: 2 | T6: 0.2 | U6: 2.5164 | V6: {=_xlfn.IFS(Suoerstore_sales[[#This Row],[Discount]]<=0.05,"0-5%",Suoerstore_sales[[#This Row],[Discount]]<=0.1,"5-10%",Suoerstore_sales[[#This Row],[Discount]]<=0.2,"10-20%",TRUE,"20%+")} -> 10-20% | W6: =YEAR(Suoerstore_sales[[#This Row],[Order Date]]) -> 2015 | X6: ="Q"&ROUNDUP(MONTH(Suoerstore_sales[[#This Row],[Order Date]])/3,0) -> Q4 | Y6: =MONTH(Suoerstore_sales[[#This Row],[Order Date]]) -> 10
A7: 6 | B7: CA-2014-115812 | C7: 41799 | D7: 41804 | E7: Standard Class | F7: BH-11710 | G7: Brosina Hoffman | H7: Consumer | I7: United States | J7: Los Angeles | K7: California | L7: 90032 | M7: West | N7: FUR-FU-10001487 | O7: Furniture | P7: Furnishings | Q7: Eldon Expressions Wood and Plastic Desk Accessories, Cherry Wood | R7: 48.86 | S7: 7 | T7: 0 | U7: 14.1694 | V7: {=_xlfn.IFS(Suoerstore_sales[[#This Row],[Discount]]<=0.05,"0-5%",Suoerstore_sales[[#This Row],[Discount]]<=0.1,"5-10%",Suoerstore_sales[[#This Row],[Discount]]<=0.2,"10-20%",TRUE,"20%+")} -> 0-5% | W7: =YEAR(Suoerstore_sales[[#This Row],[Order Date]]) -> 2014 | X7: ="Q"&ROUNDUP(MONTH(Suoerstore_sales[[#This Row],[Order Date]])/3,0) -> Q2 | Y7: =MONTH(Suoerstore_sales[[#This Row],[Order Date]]) -> 6
A8: 7 | B8: CA-2014-115812 | C8: 41799 | D8: 41804 | E8: Standard Class | F8: BH-11710 | G8: Brosina Hoffman | H8: Consumer | I8: United States | J8: Los Angeles | K8: California | L8: 90032 | M8: West | N8: OFF-AR-10002833 | O8: Office Supplies | P8: Art | Q8: Newell 322 | R8: 7.28 | S8: 4 | T8: 0 | U8: 1.9656 | V8: {=_xlfn.IFS(Suoerstore_sales[[#This Row],[Discount]]<=0.05,"0-5%",Suoerstore_sales[[#This Row],[Discount]]<=0.1,"5-10%",Suoerstore_sales[[#This Row],[Discount]]<=0.2,"10-20%",TRUE,"20%+")} -> 0-5% | W8: =YEAR(Suoerstore_sales[[#This Row],[Order Date]]) -> 2014 | X8: ="Q"&ROUNDUP(MONTH(Suoerstore_sales[[#This Row],[Order Date]])/3,0) -> Q2 | Y8: =MONTH(Suoerstore_sales[[#This Row],[Order Date]]) -> 6
A9: 8 | B9: CA-2014-115812 | C9: 41799 | D9: 41804 | E9: Standard Class | F9: BH-11710 | G9: Brosina Hoffman | H9: Consumer | I9: United States | J9: Los Angeles | K9: California | L9: 90032 | M9: West | N9: TEC-PH-10002275 | O9: Technology | P9: Phones | Q9: Mitel 5320 IP Phone VoIP phone | R9: 907.152 | S9: 6 | T9: 0.2 | U9: 90.7152 | V9: {=_xlfn.IFS(Suoerstore_sales[[#This Row],[Discount]]<=0.05,"0-5%",Suoerstore_sales[[#This Row],[Discount]]<=0.1,"5-10%",Suoerstore_sales[[#This Row],[Discount]]<=0.2,"10-20%",TRUE,"20%+")} -> 10-20% | W9: =YEAR(Suoerstore_sales[[#This Row],[Order Date]]) -> 2014 | X9: ="Q"&ROUNDUP(MONTH(Suoerstore_sales[[#This Row],[Order Date]])/3,0) -> Q2 | Y9: =MONTH(Suoerstore_sales[[#This Row],[Order Date]]) -> 6
A10: 9 | B10: CA-2014-115812 | C10: 41799 | D10: 41804 | E10: Standard Class | F10: BH-11710 | G10: Brosina Hoffman | H10: Consumer | I10: United States | J10: Los Angeles | K10: California | L10: 90032 | M10: West | N10: OFF-BI-10003910 | O10: Office Supplies | P10: Binders | Q10: DXL Angle-View Binders with Locking Rings by Samsill | R10: 18.504 | S10: 3 | T10: 0.2 | U10: 5.7825 | V10: {=_xlfn.IFS(Suoerstore_sales[[#This Row],[Discount]]<=0.05,"0-5%",Suoerstore_sales[[#This Row],[Discount]]<=0.1,"5-10%",Suoerstore_sales[[#This Row],[Discount]]<=0.2,"10-20%",TRUE,"20%+")} -> 10-20% | W10: =YEAR(Suoerstore_sales[[#This Row],[Order Date]]) -> 2014 | X10: ="Q"&ROUNDUP(MONTH(Suoerstore_sales[[#This Row],[Order Date]])/3,0) -> Q2 | Y10: =MONTH(Suoerstore_sales[[#This Row],[Order Date]]) -> 6
A11: 10 | B11: CA-2014-115812 | C11: 41799 | D11: 41804 | E11: Standard Class | F11: BH-11710 | G11: Brosina Hoffman | H11: Consumer | I11: United States | J11: Los Angeles | K11: California | L11: 90032 | M11: West | N11: OFF-AP-10002892 | O11: Office Supplies | P11: Appliances | Q11: Belkin F5C206VTEL 6 Outlet Surge | R11: 114.9 | S11: 5 | T11: 0 | U11: 34.47 | V11: {=_xlfn.IFS(Suoerstore_sales[[#This Row],[Discount]]<=0.05,"0-5%",Suoerstore_sales[[#This Row],[Discount]]<=0.1,"5-10%",Suoerstore_sales[[#This Row],[Discount]]<=0.2,"10-20%",TRUE,"20%+")} -> 0-5% | W11: =YEAR(Suoerstore_sales[[#This Row],[Order Date]]) -> 2014 | X11: ="Q"&ROUNDUP(MONTH(Suoerstore_sales[[#This Row],[Order Date]])/3,0) -> Q2 | Y11: =MONTH(Suoerstore_sales[[#This Row],[Order Date]]) -> 6
A12: 11 | B12: CA-2014-115812 | C12: 41799 | D12: 41804 | E12: Standard Class | F12: BH-11710 | G12: Brosina Hoffman | H12: Consumer | I12: United States | J12: Los Angeles | K12: California | L12: 90032 | M12: West | N12: FUR-TA-10001539 | O12: Furniture | P12: Tables | Q12: Chromcraft Rectangular Conference Tables | R12: 1706.184 | S12: 9 | T12: 0.2 | U12: 85.3092 | V12: {=_xlfn.IFS(Suoerstore_sales[[#This Row],[Discount]]<=0.05,"0-5%",Suoerstore_sales[[#This Row],[Discount]]<=0.1,"5-10%",Suoerstore_sales[[#This Row],[Discount]]<=0.2,"10-20%",TRUE,"20%+")} -> 10-20% | W12: =YEAR(Suoerstore_sales[[#This Row],[Order Date]]) -> 2014 | X12: ="Q"&ROUNDUP(MONTH(Suoerstore_sales[[#This Row],[Order Date]])/3,0) -> Q2 | Y12: =MONTH(Suoerstore_sales[[#This Row],[Order Date]]) -> 6
A13: 12 | B13: CA-2014-115812 | C13: 41799 | D13: 41804 | E13: Standard Class | F13: BH-11710 | G13: Brosina Hoffman | H13: Consumer | I13: United States | J13: Los Angeles | K13: California | L13: 90032 | M13: West | N13: TEC-PH-10002033 | O13: Technology | P13: Phones | Q13: Konftel 250 Conference phone - Charcoal black | R13: 911.424 | S13: 4 | T13: 0.2 | U13: 68.3568 | V13: {=_xlfn.IFS(Suoerstore_sales[[#This Row],[Discount]]<=0.05,"0-5%",Suoerstore_sales[[#This Row],[Discount]]<=0.1,"5-10%",Suoerstore_sales[[#This Row],[Discount]]<=0.2,"10-20%",TRUE,"20%+")} -> 10-20% | W13: =YEAR(Suoerstore_sales[[#This Row],[Order Date]]) -> 2014 | X13: ="Q"&ROUNDUP(MONTH(Suoerstore_sales[[#This Row],[Order Date]])/3,0) -> Q2 | Y13: =MONTH(Suoerstore_sales[[#This Row],[Order Date]]) -> 6
... A9995: 9994 | B9995: CA-2017-119914 | C9995: 42859 | D9995: 42864 | E9995: Second Class | F9995: CC-12220 | G9995: Chris Cortes | H9995: Consumer | I9995: United States | J9995: Westminster | K9995: California | L9995: 92683 | M9995: West | N9995: OFF-AP-10002684 | O9995: Office Supplies | P9995: Appliances | Q9995: Acco 7-Outlet Masterpiece Power Center, Wihtout Fax/Phone Line Protection | R9995: 243.16 | S9995: 2 | T9995: 0 | U9995: 72.948 | V9995: {=_xlfn.IFS(Suoerstore_sales[[#This Row],[Discount]]<=0.05,"0-5%",Suoerstore_sales[[#This Row],[Discount]]<=0.1,"5-10%",Suoerstore_sales[[#This Row],[Discount]]<=0.2,"10-20%",TRUE,"20%+")} -> 0-5% | W9995: =YEAR(Suoerstore_sales[[#This Row],[Order Date]]) -> 2017 | X9995: ="Q"&ROUNDUP(MONTH(Suoerstore_sales[[#This Row],[Order Date]])/3,0) -> Q2 | Y9995: =MONTH(Suoerstore_sales[[#This Row],[Order Date]]) -> 5

Sheet Insight_1_category
A3: Categories | B3: Profit (Sum by category) | C3: Sales (sum by category) | D3: Profit margin category | E3: Average of Discount | G3: Business Insights | H3: Results | I3: Values
A4: Technology | B4: 145454.95 | C4: 836154.03 | D4: 0.17395712 | E4: 0.13232269 | G4: Which category has highest Sales? | H4: =_xlfn.XLOOKUP(MAX(C4:C6),C4:C6,A4:A6) -> Technology | I4: =MAX(C4:C6) -> 836154.03
A5: Grand Total | B5: 145454.95 | C5: 836154.03 | D5: 0.17395712 | E5: 0.13232269 | G5: Which category has highest Profit? | H5: =_xlfn.XLOOKUP(MAX(B4:B6),B4:B6,A4:A6) -> Technology | I5: =MAX(B4:B6) -> 145454.95
G6: Which category has highest Profit Margin | H6: =_xlfn.XLOOKUP(MAX(D4:D6),D4:D6,A4:A6) -> Technology | I6: =MAX(D4:D6) -> 0.17395712
C12: Business insight statement
A33: categories | B33: Sales (sum by sub-category) | C33: Profit (sum by sub-category) | D33: Profit margin by category
A34: Furniture | B34: 741999.8 | C34: 18451.273 | D34: 0.024866951
A35: Bookcases | B35: 114880 | C35: -3472.556 | D35: -0.030227682
A36: Chairs | B36: 328449.1 | C36: 26590.166 | D36: 0.080956733
A37: Furnishings | B37: 91705.164 | C37: 13059.144 | D37: 0.14240358
A38: Tables | B38: 206965.53 | C38: -17725.481 | D38: -0.085644604
A39: Office Supplies | B39: 719047.03 | C39: 122490.8 | D39: 0.17035158
A40: Appliances | B40: 107532.16 | C40: 18138.005 | D40: 0.16867517
A41: Art | B41: 27118.792 | C41: 6527.787 | D41: 0.24071083
A42: Binders | B42: 203412.73 | C42: 30221.763 | D42: 0.14857361
A43: Envelopes | B43: 16476.402 | C43: 6964.1767 | D43: 0.42267582
A44: Fasteners | B44: 3024.28 | C44: 949.5182 | D44: 0.31396504
A45: Labels | B45: 12486.312 | C45: 5546.254 | D45: 0.44418672
... A54: Grand Total | B54: 2297200.9 | C54: 286397.02 | D54: 0.12467217
B56: sales | C56: =GETPIVOTDATA("Sales (sum by sub-category)",$A$33) -> 2297200.9
B57: profit | C57: =GETPIVOTDATA("Profit (sum by sub-category)",$A$33) -> 286397.02
B58: profit margin | C58: =GETPIVOTDATA("Profit margin by category",$A$33) -> 0.12467217

Sheet insight_2_bystate
A4: States | B4: Sales by state | C4: Profit by state
A5: Central | B5: 80166.101 | C5: -12607.887
A6: Illinois | B6: 80166.101 | C6: -12607.887
A7: Grand Total | B7: 80166.101 | C7: -12607.887

Sheet insight_3_customer
A2: Row Labels | B2: Sales by customer | C2: Profit by customer | D2: Profit margin by customer | E2: Average of Discount
A3: Aaron Bergman | B3: 886.156 | C3: 129.3465 | D3: 0.14596358 | E3: 0.066666667
A4: Aaron Hawkins | B4: 1744.7 | C4: 365.2152 | D4: 0.20932837 | E4: 0.090909091
A5: Aaron Smayling | B5: 3050.692 | C5: -253.5746 | D5: -0.083120354 | E5: 0.355
A6: Adam Bellavance | B6: 7755.62 | C6: 2054.5885 | D6: 0.26491609 | E6: 0.044444444
A7: Adam Hart | B7: 3250.337 | C7: 281.189 | D7: 0.086510722 | E7: 0.135 | N7: “High Sales + Negative Profit” customers only
A8: Adam Shillingsburg | B8: 3255.31 | C8: 64.5374 | D8: 0.01982527 | E8: 0.18 | N8: Sales Threshold | O8: 5000
A9: Adrian Barton | B9: 14473.571 | C9: 5444.8055 | D9: 0.3761895 | E9: 0.24 | I9: Top Sales by customer | J9: Sales | K9: High-sales customers against profit
A10: Adrian Hane | B10: 1735.514 | C10: -2.3146 | D10: -0.0013336683 | E10: 0.2375 | I10: {=_xlfn.TAKE(_xlfn._xlws.SORT(A3:B795,2,-1),10)} -> Sean Miller | J10: 25043.05 | K10: {=_xlfn.XLOOKUP(I10:I19,A3:A795,D3:D795)} -> -0.079093373 | N10: Name | O10: sales | P10: profit | Q10: profit margin | R10: Discount
A11: Adrian Shami | B11: 58.82 | C11: 21.8496 | D11: 0.37146549 | E11: 0.066666667 | I11: Tamara Chand | J11: 19052.218 | K11: 0.47140569 | N11: {=_xlfn._xlws.FILTER(A3:E795, (B3:B795>O8)*(C3:C795<0))} -> Alex Avila | O11: 5563.56 | P11: -362.8825 | Q11: -0.065224874 | R11: 0.090909091
A12: Aimee Bixby | B12: 966.71 | C12: 313.6597 | D12: 0.32446101 | E12: 0.13333333 | I12: Raymond Buch | J12: 15117.339 | K12: 0.46146322 | N12: Becky Martin | O12: 11789.63 | P12: -1659.9581 | Q12: -0.14079815 | R12: 0.16875
A13: Alan Barnes | B13: 1113.838 | C13: 220.813 | D13: 0.19824517 | E13: 0.13571429 | I13: Tom Ashbrook | J13: 14595.62 | K13: 0.32227396 | N13: Christine Phan | O13: 5888.275 | P13: -1850.3029 | Q13: -0.31423514 | R13: 0.21333333
A14: Alan Dominguez | B14: 6106.88 | C14: 1869.9294 | D14: 0.30620045 | E14: 0.058333333 | I14: Adrian Barton | J14: 14473.571 | K14: 0.3761895 | N14: Cindy Stewart | O14: 5690.055 | P14: -6626.3895 | Q14: -1.1645563 | R14: 0.2 | U14: Total Sales Above Threshold | X14: =SUMIFS(B3:B795, B3:B795, ">"&O8) -> 911958.27
A15: Alan Haines | B15: 1587.452 | C15: -378.5509 | D15: -0.23846447 | E15: 0.35 | I15: Ken Lonsdale | J15: 14175.229 | K15: 0.056920068 | N15: Grant Thornton | O15: 9351.212 | P15: -4108.6589 | Q15: -0.43937181 | R15: 0.25 | U15: Total Profit Above Threshold | X15: =SUMIFS(C3:C795,B3:B795,">"&O8) -> 140313.08
A16: Alan Hwang | B16: 4805.344 | C16: 1308.5546 | D16: 0.27231237 | E16: 0.092307692 | I16: Sanjit Chand | J16: 14142.334 | K16: 0.40710479 | N16: Joseph Airdo | O16: 6491.026 | P16: -819.4217 | Q16: -0.12623916 | R16: 0.2125 | U16: Average Profit Margin | X16: =AVERAGEIFS(D3:D795,B3:B795,">"&O8) -> 0.14320612
A17: Alan Schoenberger | B17: 4260.784 | C17: 719.7751 | D17: 0.1689302 | E17: 0.061538462 | I17: Hunter Lopez | J17: 12873.298 | K17: 0.43675127 | N17: Joseph Holt | O17: 7954.998 | P17: -644.6982 | Q17: -0.081043163 | R17: 0.085714286 | U17: Average Discount | X17: =AVERAGEIFS(E4:E796,B4:B796,">"&O8) -> 0.14026538
A18: Alan Shonely | B18: 584.608 | C18: 33.7158 | D18: 0.057672492 | E18: 0.26923077 | I18: Sanjit Engle | J18: 12209.438 | K18: 0.21710065 | N18: Kelly Lampkin | O18: 5016.488 | P18: -182.7813 | Q18: -0.036436108 | R18: 0.29545455
A19: Alejandro Ballentine | B19: 914.532 | C19: 264.5675 | D19: 0.28929277 | E19: 0.1 | I19: Christopher Conant | J19: 12129.072 | K19: 0.17949018 | N19: Natalie Fritzler | O19: 8322.826 | P19: -1695.9714 | Q19: -0.2037735 | R19: 0.25
A20: Alejandro Grove | B20: 2582.898 | C20: 732.7399 | D20: 0.28368906 | E20: 0.014285714 | N20: Peter Fuller | O20: 9062.864 | P20: -614.2943 | Q20: -0.067781476 | R20: 0.12105263
A21: Alejandro Savely | B21: 3214.236 | C21: 354.6276 | D21: 0.11033029 | E21: 0.225 | I21: Top Profit by customer | J21: Profit | K21: Discount with Profit | N21: Ross Baird | O21: 5633.316 | P21: -461.7332 | Q21: -0.081964726 | R21: 0.25
A22: Aleksandra Gannaway | B22: 367.548 | C22: 59.2884 | D22: 0.16130791 | E22: 0.08 | I22: {=_xlfn.TAKE(_xlfn._xlws.SORT(CHOOSE({1,2},A3:A795,C3:C795),2,-1),10)} -> Tamara Chand | J22: 8981.3239 | K22: {=-_xlfn.XLOOKUP(I22:I31,A3:A795,E3:E795)} -> -0.11666667 | N22: Sean Braxton | O22: 8057.891 | P22: -2082.7451 | Q22: -0.25847273 | R22: 0.24117647
A23: Alex Avila | B23: 5563.56 | C23: -362.8825 | D23: -0.065224874 | E23: 0.090909091 | I23: Raymond Buch | J23: 6976.0959 | K23: -0.094444444 | N23: Sean Miller | O23: 25043.05 | P23: -1980.7393 | Q23: -0.079093373 | R23: 0.24666667
A24: Alex Grayson | B24: 660.972 | C24: -5.1371 | D24: -0.0077720388 | E24: 0.23333333 | I24: Sanjit Chand | J24: 5757.4119 | K24: -0.063636364 | N24: Stefania Perrino | O24: 5440.319 | P24: -270.4282 | Q24: -0.049708151 | R24: 0.25
A25: Alex Russell | B25: 1055.694 | C25: -221.0544 | D25: -0.20939249 | E25: 0.26 | I25: Hunter Lopez | J25: 5622.4292 | K25: -0.018181818 | N25: Tom Prescott | O25: 5329.0048 | P25: -1087.3898 | Q25: -0.2040512 | R25: 0.462
A26: Alice McCarthy | B26: 814.012 | C26: 194.9878 | D26: 0.23953922 | E26: 0.125 | I26: Adrian Barton | J26: 5444.8055 | K26: -0.24 | N26: Victoria Wilson | O26: 6134.038 | P26: -874.6645 | Q26: -0.14259196 | R26: 0.16111111
A27: Allen Armold | B27: 1056.39 | C27: 277.3824 | D27: 0.26257575 | E27: 0.08 | I27: Tom Ashbrook | J27: 4703.7883 | K27: -0.08 | N27: Zuschuss Carroll | O27: 8025.707 | P27: -1032.149 | Q27: -0.12860537 | R27: 0.25483871
A28: Allen Goldenen | B28: 200.945 | C28: 69.2784 | D28: 0.34476299 | E28: 0.225 | I28: Christopher Martinez | J28: 3899.8904 | K28: -0.12
A29: Allen Rosenblatt | B29: 2236.128 | C29: -98.7646 | D29: -0.044167686 | E29: 0.1 | I29: Keith Dawkins | J29: 3038.6254 | K29: -0.0875
A30: Alyssa Crouse | B30: 925.8 | C30: -62.1342 | D30: -0.067114064 | E30: 0.32 | I30: Andy Reiter | J30: 2884.6208 | K30: -0.066666667
A31: Alyssa Tate | B31: 1171.814 | C31: 100.8768 | D31: 0.086086017 | E31: 0.2 | I31: Daniel Raglin | J31: 2869.076 | K31: -0.15384615
A32: Amy Cox | B32: 5527.846 | C32: 1366.0098 | D32: 0.2471143 | E32: 0.18888889
A33: Amy Hunt | B33: 2495.3916 | C33: -196.1201 | D33: -0.078592915 | E33: 0.14
A34: Andrew Allen | B34: 1790.512 | C34: 435.8274 | D34: 0.24340937 | E34: 0.016666667
A35: Andrew Gjertsen | B35: 2356.855 | C35: 295.6668 | D35: 0.12544972 | E35: 0.2047619
A36: Andrew Roberts | B36: 264.864 | C36: 43.6695 | D36: 0.16487518 | E36: 0.21428571
A37: Andy Gerbode | B37: 1455.038 | C37: -152.7613 | D37: -0.10498784 | E37: 0.15555556
A38: Andy Reiter | B38: 6608.448 | C38: 2884.6208 | D38: 0.43650503 | E38: 0.066666667
A39: Andy Yotov | B39: 497.014 | C39: 103.3499 | D39: 0.20794163 | E39: 0.1
A40: Anemone Ratner | B40: 88.15 | C40: 32.633 | D40: 0.37019853 | E40: 0
A41: Angele Hood | B41: 738.504 | C41: 83.963 | D41: 0.11369336 | E41: 0.12
...

Sheet insight_4_discount_senstivity
A3: Discount Band | B3: Sum of Sales | C3: Sum of Profit | D3: Sum of Profit margin
A4: 0-5% | B4: 0.47358004 | C4: 1.1207784 | D4: 0.29505019
A5: 5-10% | B5: 0.023667652 | C5: 0.031526784 | D5: 0.16607108
A6: 10-20% | B6: 0.34483397 | C6: 0.32038147 | D6: 0.11583155
A7: 20%+ | B7: 0.15791834 | C7: -0.47268668 | D7: -0.37317309
A8: Grand Total | B8: 1 | C8: 1 | D8: 0.12467217
A12: Discount Band | B12: Sum of Sales | C12: Sum of Profit
A13: 10-20% | B13: 792152.89 | C13: 91756.297
A14: Grand Total | B14: 792152.89 | C14: 91756.297

Sheet insight_5_revenue_concetration
A1: Name | B1: Sales($) | C1: Cumulative Sales | D1: Cumulative %
A2: {=_xlfn._xlws.SORT(insight_3_customer!A3:B795,2,-1)} -> Sean Miller | B2: 25043.05 | C2: =B2 -> 25043.05 | D2: =C2/$H$5 -> 0.01090155
A3: Tamara Chand | B3: 19052.218 | C3: =B3+C2 -> 44095.268 | D3: =C3/$H$5 -> 0.019195217
A4: Raymond Buch | B4: 15117.339 | C4: =B4+C3 -> 59212.607 | D4: =C4/$H$5 -> 0.025775982
A5: Tom Ashbrook | B5: 14595.62 | C5: =B5+C4 -> 73808.227 | D5: =C5/$H$5 -> 0.032129636 | G5: Total sum of sales | H5: =SUM(B2:B794) -> 2297200.9
A6: Adrian Barton | B6: 14473.571 | C6: =B6+C5 -> 88281.798 | D6: =C6/$H$5 -> 0.038430161
A7: Ken Lonsdale | B7: 14175.229 | C7: =B7+C6 -> 102457.03 | D7: =C7/$H$5 -> 0.044600813 | G7: Top 20 share in the sales
A8: Sanjit Chand | B8: 14142.334 | C8: =B8+C7 -> 116599.36 | D8: =C8/$H$5 -> 0.050757147 | G8: {=_xlfn.TAKE(_xlfn._xlws.SORT(A2:B794,2,-1),20)} -> Sean Miller | H8: 25043.05 | I8: {=_xlfn.XLOOKUP(G8:G27,A2:A794,D2:D794)} -> 0.01090155
A9: Hunter Lopez | B9: 12873.298 | C9: =B9+C8 -> 129472.66 | D9: =C9/$H$5 -> 0.056361053 | G9: Tamara Chand | H9: 19052.218 | I9: 0.019195217
A10: Sanjit Engle | B10: 12209.438 | C10: =B10+C9 -> 141682.1 | D10: =C10/$H$5 -> 0.061675972 | G10: Raymond Buch | H10: 15117.339 | I10: 0.025775982
A11: Christopher Conant | B11: 12129.072 | C11: =B11+C10 -> 153811.17 | D11: =C11/$H$5 -> 0.066955908 | G11: Tom Ashbrook | H11: 14595.62 | I11: 0.032129636
A12: Todd Sumrall | B12: 11891.751 | C12: =B12+C11 -> 165702.92 | D12: =C12/$H$5 -> 0.072132534 | G12: Adrian Barton | H12: 14473.571 | I12: 0.038430161
A13: Greg Tran | B13: 11820.12 | C13: =B13+C12 -> 177523.04 | D13: =C13/$H$5 -> 0.077277979 | G13: Ken Lonsdale | H13: 14175.229 | I13: 0.044600813
A14: Becky Martin | B14: 11789.63 | C14: =B14+C13 -> 189312.67 | D14: =C14/$H$5 -> 0.082410151 | G14: Sanjit Chand | H14: 14142.334 | I14: 0.050757147
A15: Seth Vernon | B15: 11470.95 | C15: =B15+C14 -> 200783.62 | D15: =C15/$H$5 -> 0.087403598 | G15: Hunter Lopez | H15: 12873.298 | I15: 0.056361053 | L15: 0.1153
A16: Caroline Jumper | B16: 11164.974 | C16: =B16+C15 -> 211948.59 | D16: =C16/$H$5 -> 0.092263849 | G16: Sanjit Engle | H16: 12209.438 | I16: 0.061675972
A17: Clay Ludtke | B17: 10880.546 | C17: =B17+C16 -> 222829.14 | D17: =C17/$H$5 -> 0.097000286 | G17: Christopher Conant | H17: 12129.072 | I17: 0.066955908
A18: Maria Etezadi | B18: 10663.728 | C18: =B18+C17 -> 233492.87 | D18: =C18/$H$5 -> 0.10164234 | G18: Todd Sumrall | H18: 11891.751 | I18: 0.072132534
A19: Karen Ferguson | B19: 10604.266 | C19: =B19+C18 -> 244097.13 | D19: =C19/$H$5 -> 0.10625851 | G19: Greg Tran | H19: 11820.12 | I19: 0.077277979
A20: Bill Shonely | B20: 10501.653 | C20: =B20+C19 -> 254598.79 | D20: =C20/$H$5 -> 0.11083001 | G20: Becky Martin | H20: 11789.63 | I20: 0.082410151
A21: Edward Hooks | B21: 10310.88 | C21: =B21+C20 -> 264909.67 | D21: =C21/$H$5 -> 0.11531846 | G21: Seth Vernon | H21: 11470.95 | I21: 0.087403598
A22: John Lee | B22: 9799.923 | C22: =B22+C21 -> 274709.59 | D22: =C22/$H$5 -> 0.11958449 | G22: Caroline Jumper | H22: 11164.974 | I22: 0.092263849
A23: Grant Thornton | B23: 9351.212 | C23: =B23+C22 -> 284060.8 | D23: =C23/$H$5 -> 0.12365519 | G23: Clay Ludtke | H23: 10880.546 | I23: 0.097000286
A24: Helen Wasserman | B24: 9300.254 | C24: =B24+C23 -> 293361.06 | D24: =C24/$H$5 -> 0.1277037 | G24: Maria Etezadi | H24: 10663.728 | I24: 0.10164234
A25: Tom Boeckenhauer | B25: 9133.99 | C25: =B25+C24 -> 302495.05 | D25: =C25/$H$5 -> 0.13167984 | G25: Karen Ferguson | H25: 10604.266 | I25: 0.10625851
A26: Peter Fuller | B26: 9062.864 | C26: =B26+C25 -> 311557.91 | D26: =C26/$H$5 -> 0.13562502 | G26: Bill Shonely | H26: 10501.653 | I26: 0.11083001
A27: Christopher Martinez | B27: 8954.02 | C27: =B27+C26 -> 320511.93 | D27: =C27/$H$5 -> 0.13952281 | G27: Edward Hooks | H27: 10310.88 | I27: 0.11531846
A28: Justin Deggeller | B28: 8828.0305 | C28: =B28+C27 -> 329339.96 | D28: =C28/$H$5 -> 0.14336577
A29: Joe Elijah | B29: 8697.843 | C29: =B29+C28 -> 338037.8 | D29: =C29/$H$5 -> 0.14715204
A30: Laura Armstrong | B30: 8673.222 | C30: =B30+C29 -> 346711.03 | D30: =C30/$H$5 -> 0.15092761 | G30: To reach certain range of the revenue percentage | I30: 0.5
A31: Pete Kriz | B31: 8646.934 | C31: =B31+C30 -> 355357.96 | D31: =C31/$H$5 -> 0.15469172 | G31: =COUNTIF(D2:D794,"<="&I30) -> 169
A32: Daniel Raglin | B32: 8350.868 | C32: =B32+C31 -> 363708.83 | D32: =C32/$H$5 -> 0.15832696
A33: Natalie Fritzler | B33: 8322.826 | C33: =B33+C32 -> 372031.65 | D33: =C33/$H$5 -> 0.16194999
A34: Karen Daniels | B34: 8282.358 | C34: =B34+C33 -> 380314.01 | D34: =C34/$H$5 -> 0.1655554
A35: Nick Crebassa | B35: 8241.739 | C35: =B35+C34 -> 388555.75 | D35: =C35/$H$5 -> 0.16914313
A36: Harry Marie | B36: 8236.7648 | C36: =B36+C35 -> 396792.52 | D36: =C36/$H$5 -> 0.1727287
A37: Keith Dawkins | B37: 8181.256 | C37: =B37+C36 -> 404973.77 | D37: =C37/$H$5 -> 0.1762901
A38: Sean Braxton | B38: 8057.891 | C38: =B38+C37 -> 413031.66 | D38: =C38/$H$5 -> 0.1797978
A39: Zuschuss Carroll | B39: 8025.707 | C39: =B39+C38 -> 421057.37 | D39: =C39/$H$5 -> 0.18329149
A40: Joseph Holt | B40: 7954.998 | C40: =B40+C39 -> 429012.37 | D40: =C40/$H$5 -> 0.1867544
...

Sheet insight_6_forecasting
S4: Years | U4: Growth
A5: Row Labels | B5: Sales ($) | C5: Profit($) | S5: 2014-2015 | U5: =(B62-B61)/B61 -> -0.028322271
A6: 2014 | B6: 484247.5 | C6: 49543.974 | S6: 2015-2016 | U6: =(B63-B62)/B62 -> 0.29471521
A7: Q1 | B7: 74447.796 | C7: 3811.229 | S7: 2016-2017 | U7: =(B64-B63)/B63 -> 0.20355962
A8: Q2 | B8: 86538.76 | C8: 11204.069 | X8: =(E65-E64)/E64 -> #DIV/0!
A9: Q3 | B9: 143633.21 | C9: 12804.722 | X9: =(E66-E65)/E65 -> #DIV/0!
A10: Q4 | B10: 179627.73 | C10: 21723.954 | X10: =(E67-E66)/E66 -> #DIV/0!
A11: 2015 | B11: 470532.51 | C11: 61618.604
A12: Q1 | B12: 68851.739 | C12: 9264.9416
A13: Q2 | B13: 89124.187 | C13: 12190.922
A14: Q3 | B14: 130259.58 | C14: 16853.619
A15: Q4 | B15: 182297.01 | C15: 23309.12
A16: 2016 | B16: 609205.6 | C16: 81795.174 | S16: Years | U16: Growth
A17: Q1 | B17: 93237.181 | C17: 11441.371 | S17: 2014-2015 | U17: =(C62-C61)/C61 -> 0.2437154
A18: Q2 | B18: 136082.3 | C18: 16390.339 | S18: 2015-2016 | U18: =(C63-C62)/C62 -> 0.32744284
A19: Q3 | B19: 143787.36 | C19: 15823.605 | S19: 2016-2017 | U19: =(C64-C63)/C63 -> -0.39429221
A20: Q4 | B20: 236098.75 | C20: 38139.859
A21: 2017 | B21: 733215.26 | C21: 93439.27
A22: Q1 | B22: 123144.86 | C22: 23506.203
A23: Q2 | B23: 133764.37 | C23: 15499.209
A24: Q3 | B24: 196251.96 | C24: 26985.132
A25: Q4 | B25: 280054.07 | C25: 27448.726
A26: Grand Total | B26: 2297200.9 | C26: 286397.02
T27: =_xlfn.STDEV.S(C32:C35,C37:C40,C42:C45,C47:C50) -> 0.03042526
A30: Row Labels | B30: Average of Discount | C30: Profit margin ($)
A31: 2014 | B31: 0.15828399 | C31: 0.10231126
A32: Q1 | B32: 0.15744681 | C32: 0.051193309
A33: Q2 | B33: 0.14545918 | C33: 0.1294688
A34: Q3 | B34: 0.15508865 | C34: 0.089148753
A35: Q4 | B35: 0.16764238 | C35: 0.12093876
A36: 2015 | B36: 0.15560894 | C36: 0.13095504 | S36: Years | U36: Growth
A37: Q1 | B37: 0.146 | C37: 0.13456366 | S37: 2014 | U37: =_xlfn.STDEV.S(C32:C35) -> 0.035521317
A38: Q2 | B38: 0.17162162 | C38: 0.13678579 | S38: 2015 | U38: =_xlfn.STDEV.S(C37:C40) -> 0.0042165105
A39: Q3 | B39: 0.15206081 | C39: 0.12938488 | S39: 2016 | U39: =_xlfn.STDEV.S(C42:C45) -> 0.022586676
A40: Q4 | B40: 0.1524938 | C40: 0.12786343 | S40: 2017 | U40: =_xlfn.STDEV.S(C47:C50) -> 0.040257117
A41: 2016 | B41: 0.15474295 | C41: 0.1342653
A42: Q1 | B42: 0.152 | C42: 0.12271253
A43: Q2 | B43: 0.16094276 | C43: 0.12044431
A44: Q3 | B44: 0.16075676 | C44: 0.11004865
A45: Q4 | B45: 0.14688453 | C45: 0.16154198
...

Sheet insight_7_prediction
A1: Year | B1: Revenue | C1: Profit | D1: Margin | E1: Avg Discount
A2: 2014 | B2: 484247.5 | C2: 49543.97 | D2: 0.1023 | E2: 0.1583
A3: 2015 | B3: 470532.51 | C3: 61618.6 | D3: 0.131 | E3: 0.1556
A4: 2016 | B4: 609205.6 | C4: 81795.17 | D4: 0.1343 | E4: 0.1547
A5: 2017 | B5: 733215.26 | C5: 93439.27 | D5: 0.1274 | E5: 0.1565
A6: 2018 | B6: =_xlfn.FORECAST.LINEAR(Table2[[#This Row],[Year]],B2:B5,A2:A5) -> 795694.31 | C6: =_xlfn.FORECAST.LINEAR(Table2[[#This Row],[Year]],C2:C5,A2:A5) -> 109564.87 | D6: =_xlfn.FORECAST.LINEAR(Table2[[#This Row],[Year]],D2:D5,A2:A5) -> 0.1434 | E6: =_xlfn.FORECAST.LINEAR(Table2[[#This Row],[Year]],E2:E5,A2:A5) -> 0.1547
C10: =_xlfn.FORECAST.LINEAR(Table2[[#This Row],[Year]],C6:C9,B6:B9) -> #VALUE!
A11: Metric | B11: R² | D11: =$B$6 -> 795694.31
A12: Revenue | B12: =RSQ(B2:B5,A2:A5) -> 0.86466629 | E12: =$C$6 -> 109564.87
A13: Profit | B13: =RSQ(C2:C5,A2:A5) -> 0.98810487
A14: Margin | B14: =RSQ(D2:D5,A2:A5) -> 0.48470555
A15: Discount | B15: =RSQ(E2:E5,A2:A5) -> 0.28

Sheet Dashboard
V5: =insight_3_customer!I9 -> Top Sales by customer | W5: =insight_3_customer!J9 -> Sales | X5: =insight_3_customer!K9 -> High-sales customers against profit
V6: =insight_3_customer!I10 -> Sean Miller | W6: =insight_3_customer!J10 -> 25043.05 | X6: =insight_3_customer!K10 -> -0.079093373
V7: =insight_3_customer!I11 -> Tamara Chand | W7: =insight_3_customer!J11 -> 19052.218 | X7: =insight_3_customer!K11 -> 0.47140569
V8: =insight_3_customer!I12 -> Raymond Buch | W8: =insight_3_customer!J12 -> 15117.339 | X8: =insight_3_customer!K12 -> 0.46146322
V9: =insight_3_customer!I13 -> Tom Ashbrook | W9: =insight_3_customer!J13 -> 14595.62 | X9: =insight_3_customer!K13 -> 0.32227396
V10: =insight_3_customer!I14 -> Adrian Barton | W10: =insight_3_customer!J14 -> 14473.571 | X10: =insight_3_customer!K14 -> 0.3761895
V11: =insight_3_customer!I15 -> Ken Lonsdale | W11: =insight_3_customer!J15 -> 14175.229 | X11: =insight_3_customer!K15 -> 0.056920068
V13: =insight_3_customer!I21 -> Top Profit by customer | W13: =insight_3_customer!J21 -> Profit | X13: =insight_3_customer!K21 -> Discount with Profit
V14: =insight_3_customer!I22 -> Tamara Chand | W14: =insight_3_customer!J22 -> 8981.3239 | X14: =insight_3_customer!K22 -> -0.11666667
K15: › | V15: =insight_3_customer!I23 -> Raymond Buch | W15: =insight_3_customer!J23 -> 6976.0959 | X15: =insight_3_customer!K23 -> -0.094444444
V16: =insight_3_customer!I24 -> Sanjit Chand | W16: =insight_3_customer!J24 -> 5757.4119 | X16: =insight_3_customer!K24 -> -0.063636364
V17: =insight_3_customer!I25 -> Hunter Lopez | W17: =insight_3_customer!J25 -> 5622.4292 | X17: =insight_3_customer!K25 -> -0.018181818
V18: =insight_3_customer!I26 -> Adrian Barton | W18: =insight_3_customer!J26 -> 5444.8055 | X18: =insight_3_customer!K26 -> -0.24
V19: =insight_3_customer!I27 -> Tom Ashbrook | W19: =insight_3_customer!J27 -> 4703.7883 | X19: =insight_3_customer!K27 -> -0.08
K24: ›
B42: Years | C42: Growth
B43: 2014-2015 | C43: =insight_6_forecasting!U5 -> -0.028322271
B44: 2015-2016 | C44: =insight_6_forecasting!U6 -> 0.29471521
B45: 2016-2017 | C45: =insight_6_forecasting!U7 -> 0.20355962
B54: Years | C54: Growth | Y54: Data Source: Superstore Dataset (2014–2017)
B55: 2014-2015 | C55: =insight_6_forecasting!U17 -> 0.2437154 | Y55: Forecasting: Linear Trend Projection
B56: 2015-2016 | C56: =insight_6_forecasting!U18 -> 0.32744284 | Y56: Tool: Microsoft Excel
B57: 2016-2017 | C57: =insight_6_forecasting!U19 -> -0.39429221
